Workbook
Name field_types: '⚙️ Types'!$B$7:$E$42

Sheet MethodMesh recipe
A1: MethodMesh Excel-first recipe builder
A3: How to use
A4: 1. Add ordinary study fields to survey rows 30–468.
A5: 2. Enter yes in the Include field? column only for fields that must be included in the attested recipe. Blank means excluded.
A6: 3. Copy Recipe JSON below into survey.mm_commitment_recipe calculation. Copy Canonical expression into survey.mm_canonical_commitment_live calculation.
A7: 4. Replace mm_form_id and mm_form_version calculations with the values from settings, then convert the XLSForm normally.
A8: Recipe prefix (generated; do not edit) | B8: {"schema":"methodmesh.commitment_recipe.v1","canonicalization":"ordered-kv-v1","hash_algorithm":"SHA-256","encoding":"UTF-8","pair_separator":"|","key_value_separator":"=","escaping":"none","members":[{"path":"study_id","type":"string","commitment":"value"},{"path":"form_id","type":"string","commitment":"value"},{"path":"form_version","type":"string","commitment":"value"},{"path":"workflow_instance_id","type":"string","commitment":"value"},{"path":"credential_id_sha256","type":"sha256","commitment":"text-utf8-sha256"},{"path":"credential_subject_id_sha256","type":"sha256","commitment":"text-utf8-sha256"},{"path":"issuer_public_key_fingerprint_sha256","type":"sha256","commitment":"value"},{"path":"verification_evidence_hash","type":"sha256","commitment":"value"}
A9: Recipe JSON — copy the displayed result from B9 into survey | B9: =B8&K451&"]}"
A10: Canonical expression — copy the displayed result from B10 into survey | B10: ="concat('study_id=', string(${mm_study_id}), '|', 'form_id=', string(${mm_form_id}), '|', 'form_version=', string(${mm_form_version}), '|', 'workflow_instance_id=', string(${mm_workflow_instance_id}), '|', 'credential_id_sha256=', string(${mm_credential_id_sha256}), '|', 'credential_subject_id_sha256=', string(${mm_credential_subject_id_sha256}), '|', 'issuer_public_key_fingerprint_sha256=', string(${mm_auth_issuer_public_key_fingerprint_sha256}), '|', 'verification_evidence_hash=', string(${mm_auth_verification_evidence_hash}),"&L451&")"
A12: survey row | B12: name | C12: type | D12: Include field? | E12: decision | F12: recipe type | G12: transform | H12: recipe member JSON | I12: canonical pair | J12: notes | K12: recipe accumulation | L12: canonical accumulation
A13: 30 | B13: =survey!B30 | C13: =survey!A30 | E13: =IF(OR(B13="",C13=""),"",IF(LOWER(D13)="yes","INCLUDE","EXCLUDE")) | F13: =IF(E13<>"INCLUDE","",IF(LEFT(LOWER(C13),10)="select_one ","select_one",IF(LOWER(C13)="date","date",IF(OR(LOWER(C13)="integer",LOWER(C13)="decimal",LOWER(C13)="range"),LOWER(C13),"sha256")))) | G13: =IF(E13<>"INCLUDE","",IF(F13="date","yyyy-mm-dd",IF(F13="select_one","stored-choice-name",IF(F13="sha256","odk-lexical-utf8-sha256","odk-canonical-scalar")))) | H13: =IF(E13<>"INCLUDE","","{"&CHAR(34)&"path"&CHAR(34)&":"&CHAR(34)&B13&CHAR(34)&","&CHAR(34)&"type"&CHAR(34)&":"&CHAR(34)&F13&CHAR(34)&","&CHAR(34)&"xlsform_type"&CHAR(34)&":"&CHAR(34)&C13&CHAR(34)&","&CHAR(34)&"commitment"&CHAR(34)&":"&CHAR(34)&IF(F13="sha256","text-utf8-sha256","value")&CHAR(34)&","&CHAR(34)&"transform"&CHAR(34)&":"&CHAR(34)&G13&CHAR(34)&"}") | I13: =IF(E13<>"INCLUDE","","'|"&B13&"=', "&IF(F13="date","if(string-length(string(${"&B13&"})) > 0, format-date(${"&B13&"}, '%Y-%m-%d'), '')",IF(F13="sha256","digest(string(${"&B13&"}), 'SHA-256', 'hex')","string(${"&B13&"})"))) | J13: =IF(E13="INCLUDE","Included by explicit yes","Not included") | K13: =IF(H13="","",","&H13) | L13: =IF(I13="","",I13)
A14: 31 | B14: =survey!B31 | C14: =survey!A31 | E14: =IF(OR(B14="",C14=""),"",IF(LOWER(D14)="yes","INCLUDE","EXCLUDE")) | F14: =IF(E14<>"INCLUDE","",IF(LEFT(LOWER(C14),10)="select_one ","select_one",IF(LOWER(C14)="date","date",IF(OR(LOWER(C14)="integer",LOWER(C14)="decimal",LOWER(C14)="range"),LOWER(C14),"sha256")))) | G14: =IF(E14<>"INCLUDE","",IF(F14="date","yyyy-mm-dd",IF(F14="select_one","stored-choice-name",IF(F14="sha256","odk-lexical-utf8-sha256","odk-canonical-scalar")))) | H14: =IF(E14<>"INCLUDE","","{"&CHAR(34)&"path"&CHAR(34)&":"&CHAR(34)&B14&CHAR(34)&","&CHAR(34)&"type"&CHAR(34)&":"&CHAR(34)&F14&CHAR(34)&","&CHAR(34)&"xlsform_type"&CHAR(34)&":"&CHAR(34)&C14&CHAR(34)&","&CHAR(34)&"commitment"&CHAR(34)&":"&CHAR(34)&IF(F14="sha256","text-utf8-sha256","value")&CHAR(34)&","&CHAR(34)&"transform"&CHAR(34)&":"&CHAR(34)&G14&CHAR(34)&"}") | I14: =IF(E14<>"INCLUDE","","'|"&B14&"=', "&IF(F14="date","if(string-length(string(${"&B14&"})) > 0, format-date(${"&B14&"}, '%Y-%m-%d'), '')",IF(F14="sha256","digest(string(${"&B14&"}), 'SHA-256', 'hex')","string(${"&B14&"})"))) | J14: =IF(E14="INCLUDE","Included by explicit yes","Not included") | K14: =K13&IF(H14="","",","&H14) | L14: =L13&IF(I14="","",","&I14)
A15: 32 | B15: =survey!B32 | C15: =survey!A32 | E15: =IF(OR(B15="",C15=""),"",IF(LOWER(D15)="yes","INCLUDE","EXCLUDE")) | F15: =IF(E15<>"INCLUDE","",IF(LEFT(LOWER(C15),10)="select_one ","select_one",IF(LOWER(C15)="date","date",IF(OR(LOWER(C15)="integer",LOWER(C15)="decimal",LOWER(C15)="range"),LOWER(C15),"sha256")))) | G15: =IF(E15<>"INCLUDE","",IF(F15="date","yyyy-mm-dd",IF(F15="select_one","stored-choice-name",IF(F15="sha256","odk-lexical-utf8-sha256","odk-canonical-scalar")))) | H15: =IF(E15<>"INCLUDE","","{"&CHAR(34)&"path"&CHAR(34)&":"&CHAR(34)&B15&CHAR(34)&","&CHAR(34)&"type"&CHAR(34)&":"&CHAR(34)&F15&CHAR(34)&","&CHAR(34)&"xlsform_type"&CHAR(34)&":"&CHAR(34)&C15&CHAR(34)&","&CHAR(34)&"commitment"&CHAR(34)&":"&CHAR(34)&IF(F15="sha256","text-utf8-sha256","value")&CHAR(34)&","&CHAR(34)&"transform"&CHAR(34)&":"&CHAR(34)&G15&CHAR(34)&"}") | I15: =IF(E15<>"INCLUDE","","'|"&B15&"=', "&IF(F15="date","if(string-length(string(${"&B15&"})) > 0, format-date(${"&B15&"}, '%Y-%m-%d'), '')",IF(F15="sha256","digest(string(${"&B15&"}), 'SHA-256', 'hex')","string(${"&B15&"})"))) | J15: =IF(E15="INCLUDE","Included by explicit yes","Not included") | K15: =K14&IF(H15="","",","&H15) | L15: =L14&IF(I15="","",","&I15)
A16: 33 | B16: =survey!B33 | C16: =survey!A33 | E16: =IF(OR(B16="",C16=""),"",IF(LOWER(D16)="yes","INCLUDE","EXCLUDE")) | F16: =IF(E16<>"INCLUDE","",IF(LEFT(LOWER(C16),10)="select_one ","select_one",IF(LOWER(C16)="date","date",IF(OR(LOWER(C16)="integer",LOWER(C16)="decimal",LOWER(C16)="range"),LOWER(C16),"sha256")))) | G16: =IF(E16<>"INCLUDE","",IF(F16="date","yyyy-mm-dd",IF(F16="select_one","stored-choice-name",IF(F16="sha256","odk-lexical-utf8-sha256","odk-canonical-scalar")))) | H16: =IF(E16<>"INCLUDE","","{"&CHAR(34)&"path"&CHAR(34)&":"&CHAR(34)&B16&CHAR(34)&","&CHAR(34)&"type"&CHAR(34)&":"&CHAR(34)&F16&CHAR(34)&","&CHAR(34)&"xlsform_type"&CHAR(34)&":"&CHAR(34)&C16&CHAR(34)&","&CHAR(34)&"commitment"&CHAR(34)&":"&CHAR(34)&IF(F16="sha256","text-utf8-sha256","value")&CHAR(34)&","&CHAR(34)&"transform"&CHAR(34)&":"&CHAR(34)&G16&CHAR(34)&"}") | I16: =IF(E16<>"INCLUDE","","'|"&B16&"=', "&IF(F16="date","if(string-length(string(${"&B16&"})) > 0, format-date(${"&B16&"}, '%Y-%m-%d'), '')",IF(F16="sha256","digest(string(${"&B16&"}), 'SHA-256', 'hex')","string(${"&B16&"})"))) | J16: =IF(E16="INCLUDE","Included by explicit yes","Not included") | K16: =K15&IF(H16="","",","&H16) | L16: =L15&IF(I16="","",","&I16)
A17: 34 | B17: =survey!B34 | C17: =survey!A34 | E17: =IF(OR(B17="",C17=""),"",IF(LOWER(D17)="yes","INCLUDE","EXCLUDE")) | F17: =IF(E17<>"INCLUDE","",IF(LEFT(LOWER(C17),10)="select_one ","select_one",IF(LOWER(C17)="date","date",IF(OR(LOWER(C17)="integer",LOWER(C17)="decimal",LOWER(C17)="range"),LOWER(C17),"sha256")))) | G17: =IF(E17<>"INCLUDE","",IF(F17="date","yyyy-mm-dd",IF(F17="select_one","stored-choice-name",IF(F17="sha256","odk-lexical-utf8-sha256","odk-canonical-scalar")))) | H17: =IF(E17<>"INCLUDE","","{"&CHAR(34)&"path"&CHAR(34)&":"&CHAR(34)&B17&CHAR(34)&","&CHAR(34)&"type"&CHAR(34)&":"&CHAR(34)&F17&CHAR(34)&","&CHAR(34)&"xlsform_type"&CHAR(34)&":"&CHAR(34)&C17&CHAR(34)&","&CHAR(34)&"commitment"&CHAR(34)&":"&CHAR(34)&IF(F17="sha256","text-utf8-sha256","value")&CHAR(34)&","&CHAR(34)&"transform"&CHAR(34)&":"&CHAR(34)&G17&CHAR(34)&"}") | I17: =IF(E17<>"INCLUDE","","'|"&B17&"=', "&IF(F17="date","if(string-length(string(${"&B17&"})) > 0, format-date(${"&B17&"}, '%Y-%m-%d'), '')",IF(F17="sha256","digest(string(${"&B17&"}), 'SHA-256', 'hex')","string(${"&B17&"})"))) | J17: =IF(E17="INCLUDE","Included by explicit yes","Not included") | K17: =K16&IF(H17="","",","&H17) | L17: =L16&IF(I17="","",","&I17)
A18: 35 | B18: =survey!B35 | C18: =survey!A35 | E18: =IF(OR(B18="",C18=""),"",IF(LOWER(D18)="yes","INCLUDE","EXCLUDE")) | F18: =IF(E18<>"INCLUDE","",IF(LEFT(LOWER(C18),10)="select_one ","select_one",IF(LOWER(C18)="date","date",IF(OR(LOWER(C18)="integer",LOWER(C18)="decimal",LOWER(C18)="range"),LOWER(C18),"sha256")))) | G18: =IF(E18<>"INCLUDE","",IF(F18="date","yyyy-mm-dd",IF(F18="select_one","stored-choice-name",IF(F18="sha256","odk-lexical-utf8-sha256","odk-canonical-scalar")))) | H18: =IF(E18<>"INCLUDE","","{"&CHAR(34)&"path"&CHAR(34)&":"&CHAR(34)&B18&CHAR(34)&","&CHAR(34)&"type"&CHAR(34)&":"&CHAR(34)&F18&CHAR(34)&","&CHAR(34)&"xlsform_type"&CHAR(34)&":"&CHAR(34)&C18&CHAR(34)&","&CHAR(34)&"commitment"&CHAR(34)&":"&CHAR(34)&IF(F18="sha256","text-utf8-sha256","value")&CHAR(34)&","&CHAR(34)&"transform"&CHAR(34)&":"&CHAR(34)&G18&CHAR(34)&"}") | I18: =IF(E18<>"INCLUDE","","'|"&B18&"=', "&IF(F18="date","if(string-length(string(${"&B18&"})) > 0, format-date(${"&B18&"}, '%Y-%m-%d'), '')",IF(F18="sha256","digest(string(${"&B18&"}), 'SHA-256', 'hex')","string(${"&B18&"})"))) | J18: =IF(E18="INCLUDE","Included by explicit yes","Not included") | K18: =K17&IF(H18="","",","&H18) | L18: =L17&IF(I18="","",","&I18)
A19: 36 | B19: =survey!B36 | C19: =survey!A36 | E19: =IF(OR(B19="",C19=""),"",IF(LOWER(D19)="yes","INCLUDE","EXCLUDE")) | F19: =IF(E19<>"INCLUDE","",IF(LEFT(LOWER(C19),10)="select_one ","select_one",IF(LOWER(C19)="date","date",IF(OR(LOWER(C19)="integer",LOWER(C19)="decimal",LOWER(C19)="range"),LOWER(C19),"sha256")))) | G19: =IF(E19<>"INCLUDE","",IF(F19="date","yyyy-mm-dd",IF(F19="select_one","stored-choice-name",IF(F19="sha256","odk-lexical-utf8-sha256","odk-canonical-scalar")))) | H19: =IF(E19<>"INCLUDE","","{"&CHAR(34)&"path"&CHAR(34)&":"&CHAR(34)&B19&CHAR(34)&","&CHAR(34)&"type"&CHAR(34)&":"&CHAR(34)&F19&CHAR(34)&","&CHAR(34)&"xlsform_type"&CHAR(34)&":"&CHAR(34)&C19&CHAR(34)&","&CHAR(34)&"commitment"&CHAR(34)&":"&CHAR(34)&IF(F19="sha256","text-utf8-sha256","value")&CHAR(34)&","&CHAR(34)&"transform"&CHAR(34)&":"&CHAR(34)&G19&CHAR(34)&"}") | I19: =IF(E19<>"INCLUDE","","'|"&B19&"=', "&IF(F19="date","if(string-length(string(${"&B19&"})) > 0, format-date(${"&B19&"}, '%Y-%m-%d'), '')",IF(F19="sha256","digest(string(${"&B19&"}), 'SHA-256', 'hex')","string(${"&B19&"})"))) | J19: =IF(E19="INCLUDE","Included by explicit yes","Not included") | K19: =K18&IF(H19="","",","&H19) | L19: =L18&IF(I19="","",","&I19)
A20: 37 | B20: =survey!B37 | C20: =survey!A37 | E20: =IF(OR(B20="",C20=""),"",IF(LOWER(D20)="yes","INCLUDE","EXCLUDE")) | F20: =IF(E20<>"INCLUDE","",IF(LEFT(LOWER(C20),10)="select_one ","select_one",IF(LOWER(C20)="date","date",IF(OR(LOWER(C20)="integer",LOWER(C20)="decimal",LOWER(C20)="range"),LOWER(C20),"sha256")))) | G20: =IF(E20<>"INCLUDE","",IF(F20="date","yyyy-mm-dd",IF(F20="select_one","stored-choice-name",IF(F20="sha256","odk-lexical-utf8-sha256","odk-canonical-scalar")))) | H20: =IF(E20<>"INCLUDE","","{"&CHAR(34)&"path"&CHAR(34)&":"&CHAR(34)&B20&CHAR(34)&","&CHAR(34)&"type"&CHAR(34)&":"&CHAR(34)&F20&CHAR(34)&","&CHAR(34)&"xlsform_type"&CHAR(34)&":"&CHAR(34)&C20&CHAR(34)&","&CHAR(34)&"commitment"&CHAR(34)&":"&CHAR(34)&IF(F20="sha256","text-utf8-sha256","value")&CHAR(34)&","&CHAR(34)&"transform"&CHAR(34)&":"&CHAR(34)&G20&CHAR(34)&"}") | I20: =IF(E20<>"INCLUDE","","'|"&B20&"=', "&IF(F20="date","if(string-length(string(${"&B20&"})) > 0, format-date(${"&B20&"}, '%Y-%m-%d'), '')",IF(F20="sha256","digest(string(${"&B20&"}), 'SHA-256', 'hex')","string(${"&B20&"})"))) | J20: =IF(E20="INCLUDE","Included by explicit yes","Not included") | K20: =K19&IF(H20="","",","&H20) | L20: =L19&IF(I20="","",","&I20)
A21: 38 | B21: =survey!B38 | C21: =survey!A38 | E21: =IF(OR(B21="",C21=""),"",IF(LOWER(D21)="yes","INCLUDE","EXCLUDE")) | F21: =IF(E21<>"INCLUDE","",IF(LEFT(LOWER(C21),10)="select_one ","select_one",IF(LOWER(C21)="date","date",IF(OR(LOWER(C21)="integer",LOWER(C21)="decimal",LOWER(C21)="range"),LOWER(C21),"sha256")))) | G21: =IF(E21<>"INCLUDE","",IF(F21="date","yyyy-mm-dd",IF(F21="select_one","stored-choice-name",IF(F21="sha256","odk-lexical-utf8-sha256","odk-canonical-scalar")))) | H21: =IF(E21<>"INCLUDE","","{"&CHAR(34)&"path"&CHAR(34)&":"&CHAR(34)&B21&CHAR(34)&","&CHAR(34)&"type"&CHAR(34)&":"&CHAR(34)&F21&CHAR(34)&","&CHAR(34)&"xlsform_type"&CHAR(34)&":"&CHAR(34)&C21&CHAR(34)&","&CHAR(34)&"commitment"&CHAR(34)&":"&CHAR(34)&IF(F21="sha256","text-utf8-sha256","value")&CHAR(34)&","&CHAR(34)&"transform"&CHAR(34)&":"&CHAR(34)&G21&CHAR(34)&"}") | I21: =IF(E21<>"INCLUDE","","'|"&B21&"=', "&IF(F21="date","if(string-length(string(${"&B21&"})) > 0, format-date(${"&B21&"}, '%Y-%m-%d'), '')",IF(F21="sha256","digest(string(${"&B21&"}), 'SHA-256', 'hex')","string(${"&B21&"})"))) | J21: =IF(E21="INCLUDE","Included by explicit yes","Not included") | K21: =K20&IF(H21="","",","&H21) | L21: =L20&IF(I21="","",","&I21)
A22: 39 | B22: =survey!B39 | C22: =survey!A39 | E22: =IF(OR(B22="",C22=""),"",IF(LOWER(D22)="yes","INCLUDE","EXCLUDE")) | F22: =IF(E22<>"INCLUDE","",IF(LEFT(LOWER(C22),10)="select_one ","select_one",IF(LOWER(C22)="date","date",IF(OR(LOWER(C22)="integer",LOWER(C22)="decimal",LOWER(C22)="range"),LOWER(C22),"sha256")))) | G22: =IF(E22<>"INCLUDE","",IF(F22="date","yyyy-mm-dd",IF(F22="select_one","stored-choice-name",IF(F22="sha256","odk-lexical-utf8-sha256","odk-canonical-scalar")))) | H22: =IF(E22<>"INCLUDE","","{"&CHAR(34)&"path"&CHAR(34)&":"&CHAR(34)&B22&CHAR(34)&","&CHAR(34)&"type"&CHAR(34)&":"&CHAR(34)&F22&CHAR(34)&","&CHAR(34)&"xlsform_type"&CHAR(34)&":"&CHAR(34)&C22&CHAR(34)&","&CHAR(34)&"commitment"&CHAR(34)&":"&CHAR(34)&IF(F22="sha256","text-utf8-sha256","value")&CHAR(34)&","&CHAR(34)&"transform"&CHAR(34)&":"&CHAR(34)&G22&CHAR(34)&"}") | I22: =IF(E22<>"INCLUDE","","'|"&B22&"=', "&IF(F22="date","if(string-length(string(${"&B22&"})) > 0, format-date(${"&B22&"}, '%Y-%m-%d'), '')",IF(F22="sha256","digest(string(${"&B22&"}), 'SHA-256', 'hex')","string(${"&B22&"})"))) | J22: =IF(E22="INCLUDE","Included by explicit yes","Not included") | K22: =K21&IF(H22="","",","&H22) | L22: =L21&IF(I22="","",","&I22)
A23: 40 | B23: =survey!B40 | C23: =survey!A40 | E23: =IF(OR(B23="",C23=""),"",IF(LOWER(D23)="yes","INCLUDE","EXCLUDE")) | F23: =IF(E23<>"INCLUDE","",IF(LEFT(LOWER(C23),10)="select_one ","select_one",IF(LOWER(C23)="date","date",IF(OR(LOWER(C23)="integer",LOWER(C23)="decimal",LOWER(C23)="range"),LOWER(C23),"sha256")))) | G23: =IF(E23<>"INCLUDE","",IF(F23="date","yyyy-mm-dd",IF(F23="select_one","stored-choice-name",IF(F23="sha256","odk-lexical-utf8-sha256","odk-canonical-scalar")))) | H23: =IF(E23<>"INCLUDE","","{"&CHAR(34)&"path"&CHAR(34)&":"&CHAR(34)&B23&CHAR(34)&","&CHAR(34)&"type"&CHAR(34)&":"&CHAR(34)&F23&CHAR(34)&","&CHAR(34)&"xlsform_type"&CHAR(34)&":"&CHAR(34)&C23&CHAR(34)&","&CHAR(34)&"commitment"&CHAR(34)&":"&CHAR(34)&IF(F23="sha256","text-utf8-sha256","value")&CHAR(34)&","&CHAR(34)&"transform"&CHAR(34)&":"&CHAR(34)&G23&CHAR(34)&"}") | I23: =IF(E23<>"INCLUDE","","'|"&B23&"=', "&IF(F23="date","if(string-length(string(${"&B23&"})) > 0, format-date(${"&B23&"}, '%Y-%m-%d'), '')",IF(F23="sha256","digest(string(${"&B23&"}), 'SHA-256', 'hex')","string(${"&B23&"})"))) | J23: =IF(E23="INCLUDE","Included by explicit yes","Not included") | K23: =K22&IF(H23="","",","&H23) | L23: =L22&IF(I23="","",","&I23)
A24: 41 | B24: =survey!B41 | C24: =survey!A41 | E24: =IF(OR(B24="",C24=""),"",IF(LOWER(D24)="yes","INCLUDE","EXCLUDE")) | F24: =IF(E24<>"INCLUDE","",IF(LEFT(LOWER(C24),10)="select_one ","select_one",IF(LOWER(C24)="date","date",IF(OR(LOWER(C24)="integer",LOWER(C24)="decimal",LOWER(C24)="range"),LOWER(C24),"sha256")))) | G24: =IF(E24<>"INCLUDE","",IF(F24="date","yyyy-mm-dd",IF(F24="select_one","stored-choice-name",IF(F24="sha256","odk-lexical-utf8-sha256","odk-canonical-scalar")))) | H24: =IF(E24<>"INCLUDE","","{"&CHAR(34)&"path"&CHAR(34)&":"&CHAR(34)&B24&CHAR(34)&","&CHAR(34)&"type"&CHAR(34)&":"&CHAR(34)&F24&CHAR(34)&","&CHAR(34)&"xlsform_type"&CHAR(34)&":"&CHAR(34)&C24&CHAR(34)&","&CHAR(34)&"commitment"&CHAR(34)&":"&CHAR(34)&IF(F24="sha256","text-utf8-sha256","value")&CHAR(34)&","&CHAR(34)&"transform"&CHAR(34)&":"&CHAR(34)&G24&CHAR(34)&"}") | I24: =IF(E24<>"INCLUDE","","'|"&B24&"=', "&IF(F24="date","if(string-length(string(${"&B24&"})) > 0, format-date(${"&B24&"}, '%Y-%m-%d'), '')",IF(F24="sha256","digest(string(${"&B24&"}), 'SHA-256', 'hex')","string(${"&B24&"})"))) | J24: =IF(E24="INCLUDE","Included by explicit yes","Not included") | K24: =K23&IF(H24="","",","&H24) | L24: =L23&IF(I24="","",","&I24)
A25: 42 | B25: =survey!B42 | C25: =survey!A42 | E25: =IF(OR(B25="",C25=""),"",IF(LOWER(D25)="yes","INCLUDE","EXCLUDE")) | F25: =IF(E25<>"INCLUDE","",IF(LEFT(LOWER(C25),10)="select_one ","select_one",IF(LOWER(C25)="date","date",IF(OR(LOWER(C25)="integer",LOWER(C25)="decimal",LOWER(C25)="range"),LOWER(C25),"sha256")))) | G25: =IF(E25<>"INCLUDE","",IF(F25="date","yyyy-mm-dd",IF(F25="select_one","stored-choice-name",IF(F25="sha256","odk-lexical-utf8-sha256","odk-canonical-scalar")))) | H25: =IF(E25<>"INCLUDE","","{"&CHAR(34)&"path"&CHAR(34)&":"&CHAR(34)&B25&CHAR(34)&","&CHAR(34)&"type"&CHAR(34)&":"&CHAR(34)&F25&CHAR(34)&","&CHAR(34)&"xlsform_type"&CHAR(34)&":"&CHAR(34)&C25&CHAR(34)&","&CHAR(34)&"commitment"&CHAR(34)&":"&CHAR(34)&IF(F25="sha256","text-utf8-sha256","value")&CHAR(34)&","&CHAR(34)&"transform"&CHAR(34)&":"&CHAR(34)&G25&CHAR(34)&"}") | I25: =IF(E25<>"INCLUDE","","'|"&B25&"=', "&IF(F25="date","if(string-length(string(${"&B25&"})) > 0, format-date(${"&B25&"}, '%Y-%m-%d'), '')",IF(F25="sha256","digest(string(${"&B25&"}), 'SHA-256', 'hex')","string(${"&B25&"})"))) | J25: =IF(E25="INCLUDE","Included by explicit yes","Not included") | K25: =K24&IF(H25="","",","&H25) | L25: =L24&IF(I25="","",","&I25)
... A451: 468 | B451: =survey!B468 | C451: =survey!A468 | E451: =IF(OR(B451="",C451=""),"",IF(LOWER(D451)="yes","INCLUDE","EXCLUDE")) | F451: =IF(E451<>"INCLUDE","",IF(LEFT(LOWER(C451),10)="select_one ","select_one",IF(LOWER(C451)="date","date",IF(OR(LOWER(C451)="integer",LOWER(C451)="decimal",LOWER(C451)="range"),LOWER(C451),"sha256")))) | G451: =IF(E451<>"INCLUDE","",IF(F451="date","yyyy-mm-dd",IF(F451="select_one","stored-choice-name",IF(F451="sha256","odk-lexical-utf8-sha256","odk-canonical-scalar")))) | H451: =IF(E451<>"INCLUDE","","{"&CHAR(34)&"path"&CHAR(34)&":"&CHAR(34)&B451&CHAR(34)&","&CHAR(34)&"type"&CHAR(34)&":"&CHAR(34)&F451&CHAR(34)&","&CHAR(34)&"xlsform_type"&CHAR(34)&":"&CHAR(34)&C451&CHAR(34)&","&CHAR(34)&"commitment"&CHAR(34)&":"&CHAR(34)&IF(F451="sha256","text-utf8-sha256","value")&CHAR(34)&","&CHAR(34)&"transform"&CHAR(34)&":"&CHAR(34)&G451&CHAR(34)&"}") | I451: =IF(E451<>"INCLUDE","","'|"&B451&"=', "&IF(F451="date","if(string-length(string(${"&B451&"})) > 0, format-date(${"&B451&"}, '%Y-%m-%d'), '')",IF(F451="sha256","digest(string(${"&B451&"}), 'SHA-256', 'hex')","string(${"&B451&"})"))) | J451: =IF(E451="INCLUDE","Included by explicit yes","Not included") | K451: =K450&IF(H451="","",","&H451) | L451: =L450&IF(I451="","",","&I451)

Sheet survey
A1: type | B1: name | C1: label | D1: hint | E1: required | F1: relevant | G1: appearance | H1: default | I1: constraint | J1: constraint_message | K1: calculation | L1: trigger | M1: choice_filter | N1: parameters | O1: repeat_count | P1: note | Q1: image | R1: audio | S1: video | T1: readonly | U1: body::intent
A2: calculate | B2: mm_workflow_instance_id | G2: hidden-answer | K2: once(uuid())
A3: calculate | B3: mm_study_id | G3: hidden-answer | K3: ''
A4: calculate | B4: mm_form_id | G4: hidden-answer | K4: ''
A5: calculate | B5: mm_form_version | G5: hidden-answer | K5: ''
A6: calculate | B6: mm_timestamp_policy | G6: hidden-answer | K6: 'preferred'
A7: begin group | B7: mm_authenticate_operator | C7: Authenticate operator | D7: Tap the NFC staff credential and enter its PIN. | G7: field-list | U7: com.example.methodmesh.EXECUTE_METHOD(method_id='nfc_credential_verification',caller='odk',input_payload_mode='FULL',return_mode='flat',methodmesh_return_namespace='mm_auth')
A8: text | B8: mm_auth_methodmesh_execution_id | C8: MethodMesh authentication return: methodmesh_execution_id | G8: hidden-answer | T8: yes
A9: text | B9: mm_auth_methodmesh_method_id | C9: MethodMesh authentication return: methodmesh_method_id | G9: hidden-answer | T9: yes
A10: text | B10: mm_auth_methodmesh_status | C10: MethodMesh authentication return: methodmesh_status | G10: hidden-answer | T10: yes
A11: text | B11: mm_auth_credential_verified | C11: MethodMesh authentication return: credential_verified | G11: hidden-answer | T11: yes
A12: text | B12: mm_auth_credential_verification_message | C12: MethodMesh authentication return: credential_verification_message | G12: hidden-answer | T12: yes
A13: text | B13: mm_auth_credential_id | C13: MethodMesh authentication return: credential_id | G13: hidden-answer | T13: yes
A14: text | B14: mm_auth_credential_subject_id | C14: MethodMesh authentication return: credential_subject_id | G14: hidden-answer | T14: yes
A15: text | B15: mm_auth_valid_until_iso | C15: MethodMesh authentication return: valid_until_iso | G15: hidden-answer | T15: yes
A16: text | B16: mm_auth_pin_verified | C16: MethodMesh authentication return: pin_verified | G16: hidden-answer | T16: yes
A17: text | B17: mm_auth_issuer_signature_valid | C17: MethodMesh authentication return: issuer_signature_valid | G17: hidden-answer | T17: yes
A18: text | B18: mm_auth_issuer_trust_status | C18: MethodMesh authentication return: issuer_trust_status | G18: hidden-answer | T18: yes
A19: text | B19: mm_auth_issuer_key_id | C19: MethodMesh authentication return: issuer_key_id | G19: hidden-answer | T19: yes
... A25: text | B25: mm_auth_methodmesh_full_json | C25: MethodMesh authentication return: methodmesh_full_json | G25: hidden-answer | T25: yes
A26: end group | B26: mm_authenticate_operator_end
A27: calculate | B27: mm_auth_ok | G27: hidden-answer | K27: if(${mm_auth_methodmesh_status} = 'Succeeded' and ${mm_auth_credential_verified} = 'true' and ${mm_auth_pin_verified} = 'true' and ${mm_auth_issuer_signature_valid} = 'true', 'true', 'false')
A28: note | B28: mm_auth_status_ok | C28: Credential verified | F28: ${mm_auth_ok} = 'true'
A29: begin group | B29: mm_study_data | C29: Study data | D29: Add ordinary study questions in rows 30–468. Mark inclusion on the MethodMesh recipe sheet. | F29: ${mm_auth_ok} = 'true'
A469: end group | B469: mm_study_data_end
A471: calculate | B471: mm_credential_id_sha256 | G471: hidden-answer | K471: digest(string(${mm_auth_credential_id}), 'SHA-256', 'hex')
A472: calculate | B472: mm_credential_subject_id_sha256 | G472: hidden-answer | K472: digest(string(${mm_auth_credential_subject_id}), 'SHA-256', 'hex')
A473: calculate | B473: mm_canonical_commitment_live | G473: hidden-answer | K473: PASTE_CANONICAL_EXPRESSION_FROM_METHODMESH_RECIPE_SHEET
A474: calculate | B474: mm_current_event_payload_hash | G474: hidden-answer | K474: digest(${mm_canonical_commitment_live}, 'SHA-256', 'hex')
A475: select_one mm_yes | B475: mm_finalize_for_attestation | C475: Finalize these data for attestation? | E475: yes | F475: ${mm_auth_ok} = 'true' | I475: . = 'yes' | J475: Select Yes to freeze the study data before attestation.
A476: calculate | B476: mm_frozen_canonical_commitment | G476: hidden-answer | K476: once(if(${mm_finalize_for_attestation} = 'yes', ${mm_canonical_commitment_live}, ''))
A477: calculate | B477: mm_event_payload_hash | G477: hidden-answer | K477: once(if(string-length(${mm_frozen_canonical_commitment}) > 0, digest(${mm_frozen_canonical_commitment}, 'SHA-256', 'hex'), ''))
A478: calculate | B478: mm_commitment_recipe | G478: hidden-answer | K478: PASTE_RECIPE_JSON_FROM_METHODMESH_RECIPE_SHEET
A479: calculate | B479: mm_current_data_matches_frozen_commitment | G479: hidden-answer | K479: if(${mm_current_event_payload_hash} = ${mm_event_payload_hash}, 'true', 'false')
A480: begin group | B480: mm_create_attestation | C480: Create MethodMesh attestation | D480: This signs the frozen study-data commitment. | F480: string-length(${mm_event_payload_hash}) = 64 and ${mm_current_data_matches_frozen_commitment} = 'true' | G480: field-list | U480: com.example.methodmesh.EXECUTE_METHOD(method_id='attestation.create',caller='odk',form_id=${mm_form_id},form_version=${mm_form_version},form_instance_id=${mm_workflow_instance_id},operator_id=${mm_auth_credential_subject_id},input_event_type='odk_form_commitment',input_event_payload_hash=${mm_event_payload_hash},input_commitment_recipe=${mm_commitment_recipe},input_attestation_method_version='1.2.0',input_attestation_schema_version='4',input_verification_method='NfcCredential',input_verification_execution_id=${mm_auth_methodmesh_execution_id},input_trusted_timestamp=${mm_timestamp_policy},input_payload_mode='FULL',return_mode='flat',methodmesh_return_namespace='mm_att')
A481: text | B481: mm_att_methodmesh_execution_id | C481: MethodMesh attestation return: methodmesh_execution_id | G481: hidden-answer | T481: yes
A482: text | B482: mm_att_methodmesh_status | C482: MethodMesh attestation return: methodmesh_status | G482: hidden-answer | T482: yes
A483: text | B483: mm_att_attestation_id | C483: MethodMesh attestation return: attestation_id | G483: hidden-answer | T483: yes
A484: text | B484: mm_att_event_payload_hash | C484: MethodMesh attestation return: event_payload_hash | G484: hidden-answer | T484: yes
A485: text | B485: mm_att_attestation_schema_version | C485: MethodMesh attestation return: attestation_schema_version | G485: hidden-answer | T485: yes
...

Sheet choices
A1: list_name | B1: name | C1: label
A500: mm_yes | B500: yes | C500: Yes

Sheet settings
A1: form_title | B1: form_id | C1: version | D1: instance_name | E1: default_language | F1: style
C2: =TEXT(NOW(), "yyyymmddhhmmss")

Sheet entities
A1: list_name | B1: label

Sheet 👋 Start here
C1: Getting started with XLSForms | H1: Last update | I1: License
H2: 45982 | I2: CC BY-SA
B4: - The XLSForm standard lets you create powerful forms for the ODK ecosystem.
B5: - A form is defined using 4 sheets:
B6: - The survey sheet defines the questions and logic for your form. It is required.
B7: - The choices sheet defines choices to use in select questions.
B8: - The settings sheet defines form metadata and configuration.
B9: - The entities sheet is used to create entities from form values for use in longitudinal workflows, case management, and more.
B11: - The template sheets contain the most common columns. See the Translations and Additional columns sheets for other columns.
B12: - Hover over column names to see a note about how they can be used.
B13: - Columns colored in green on the survey and choices sheets can be translated.
B15: 💡 Use File > Make a copy to make a copy of this template that you can edit
B16: 💡 Using a consistent column order makes it easier to copy and paste between different form definitions.
B17: 💡 Consider hiding columns you don't need instead of deleting them.
... B29: Changelog
B30: 45982 | C30: Add hidden type, big-image additional column
B31: 45631 | C31: Add counter appearance
B32: 45481 | C32: Add masked appearance
B33: 45474 | C33: Add table-list, hidden-answer and printer appearances
B34: 45335 | C34: no-calendar appearance does not work for Enketo
B35: 45320 | C35: Add entity_id and update_if to "Additional columns", add table-list to appearances, add grid theme reference
B36: 45232 | C36: Add decimal and text numbers for thousands-sep appearance; add filters on types, appearances and additional columns sheets (thanks @wroos!)
B37: 45223 | C37: Add Make a copy tip to readme
B38: 45215 | C38: v2023.1 release

Sheet ⚙️ Types
B1: Types
B3: The survey sheet's 'type' column determines how the user will be prompted or what will be computed by the form | F3: 📋 Form with all question types
B4: 💡 See the Appearances sheet to learn how to modify how a question is displayed to users
B5: 💡 The parameters column is sometimes used to configure aspects of a question type that are not appearance-related
B7: Field type | C7: Description | D7: Collect mobile forms | E7: Enketo web forms | F7: Parameters
B8: text | C8: Prompt the user for a text response | D8: Yes | E8: Yes
B9: integer | C9: Prompt the user for an integer response | D9: Yes | E9: Yes
B10: decimal | C10: Prompt the user for a decimal response | D10: Yes | E10: Yes
B11: note | C11: Show the user some text | D11: Yes | E11: Yes
B12: calculate | C12: Record the result of an expression specified in the calculation column | D12: Yes | E12: Yes
B13: select_one list_name | C13: Prompt the user to select one choice out of a list | D13: Yes | E13: Yes | F13: randomize, seed
B14: select_multiple list_name | C14: Prompt the user to select multiple choices out of a list | D14: Yes | E14: Yes | F14: randomize, seed
B15: select_one_from_file file.extension | C15: Prompt the user to select one choice out of a list of choices from a file | D15: Yes | E15: Yes | F15: randomize, seed, value, label
B16: select_multiple_from_file file.extension | C16: Prompt the user to select multiple choices out of a list of choices from a file | D16: Yes | E16: Yes | F16: randomize, seed, value, label
B17: begin_repeat | C17: Indicate the start of a group of questions that are repeated | D17: Yes | E17: Yes
B18: end_repeat | C18: Indicate the end of a group of questions that are repeated | D18: Yes | E18: Yes
B19: begin_group | C19: Indicate the start of a group of questions | D19: Yes | E19: Yes
B20: end_group | C20: Indicate the end of a group of questions | D20: Yes | E20: Yes
B21: geopoint | C21: Prompt the user to record a single point (a location) | D21: Yes | E21: Yes | F21: capture-accuracy, warning-accuracy, allow-mock-accuracy
B22: geotrace | C22: Prompt the user to record a line of points | D22: Yes | E22: Yes
B23: geoshape | C23: Prompt the user to record a polygon of points (first and last point are identical) | D23: Yes | E23: Yes
B24: start-geopoint | C24: Record the highest-accuracy point within 20 seconds of creating the blank filled form | D24: Yes | E24: Yes
B25: range | C25: Prompt the user to select a value in an integer or decimal range defined in the parameters column | D25: Yes | E25: Yes | F25: start, end, step
B26: image | C26: Prompt the user for an image | D26: Yes | E26: Yes | F26: max-pixels
B27: barcode | C27: Prompt the user to scan a barcode | D27: Yes | E27: No
B28: audio | C28: Prompt the user to record or select audio | D28: Yes | E28: Yes | F28: quality (normal, low, voice-only, external; defaults to normal)
B29: background-audio | C29: Record audio in the background while filling out the form | D29: Yes | E29: No | F29: quality (normal, low, voice-only)
B30: video | C30: Prompt the user to record or select a video | D30: Yes | E30: Yes
B31: file | C31: Prompt the user to attach a file | D31: Yes | E31: Yes
B32: date | C32: Prompt the user for a date response | D32: Yes | E32: Yes
B33: time | C33: Prompt the user for a time response | D33: Yes | E33: Yes
B34: datetime | C34: Prompt the user for a date and time response | D34: Yes | E34: Yes
B35: rank | C35: Prompt the user to rank a list of choices | D35: Yes | E35: Yes
B36: csv-external | C36: Attach a CSV to the form for querying. Specify its name without extension in the name column | D36: Yes | E36: Yes
B37: acknowledge | C37: Prompt the user to acknowledge a statement | D37: Yes | E37: Yes
B38: start | C38: Record the time when the blank filled form is created | D38: Yes | E38: Yes
B39: end | C39: Record the time the last time that the filled form is finalized | D39: Yes | E39: Yes
B40: today | C40: Record the date when the blank filled form is created | D40: Yes | E40: Yes
B41: deviceid | C41: Record the install's unique ID (reset on uninstall or cache clear) | D41: Yes | E41: Yes
... B45: hidden | C45: Hidden field that can record the result of a calculation, have a default value, or have no value at all. | D45: Yes | E45: Yes
...

Sheet 👀 Appearances
B1: Appearances
B3: Appearances configure how a question will be displayed to the user on their device
B4: 💡 Most appearances for the same question type can be combined by using a space-separated list
B6: Appearance name | C6: Description | D6: Type(s) used with | E6: Collect mobile forms | F6: Enketo web forms
B7: numbers | C7: Restrict input to numeric symbols but save the value as text | D7: text | E7: Yes | F7: depends on browser
B8: multiline | C8: Show a text area that is multiple lines tall | D8: text | E8: No (text boxes grow vertically as needed) | F8: Yes
B9: url | C9: Show a button to launch the website represented by this field's value | D9: text | E9: Yes | F9: Yes
B10: ex: | C10: Add the Android app ID of a custom application after the ex: prefix to launch that application | D10: text integer decimal image audio video file | E10: Yes | F10: No
B11: thousands-sep | C11: Automatically add locale-dependent thousands separators on screen but not in submissions | D11: integer, decimal, text numbers | E11: Yes | F11: Yes
B12: bearing | C12: Prompt the user to capture the device-reported compass direction | D12: decimal | E12: Yes | F12: No
B13: vertical | C13: Show a vertical range slider instead of the default horizontal slider | D13: range | E13: Yes | F13: Yes
B14: no-ticks | C14: Hide tick marks for a range slider (can combine with vertical) | D14: range | E14: Yes | F14: Yes
B15: picker | C15: Show values in a range as a list of options that can be picked | D15: range | E15: Yes | F15: Yes
B16: rating | C16: Show values in a range as star ratings | D16: range | E16: Yes | F16: Yes
B17: new | C17: Only show the option to capture new media, not to select existing | D17: image audio video | E17: Yes | F17: depends on browser
... B52: counter | C52: Show buttons for incrementing and decrementing | D52: integer | E52: Yes | F52: No

Sheet 🔀 Relevance
B1: Relevance
B3: Relevance determines whether a question will be displayed to a user or not. It lets you define branching or skip logic in your forms.
B4: 💡 Apply relevance to groups or repeats to skip or show multiple questions at once
B5: 💡 You can use relevance on a note to provide additional guidance or to confirm a value that could possibly be out of range
B6: 💡 You can meet almost any requirement with available functions
B8: Example relevance expression | C8: Description
B9: ${q1} != '' | C9: This question will appear if q1 was not blank
B10: ${age} < 18 | C10: This question will only appear if previously-entered age was less than 18
B11: ${random_value} < 0.5 | C11: If ${random_value} is a calculate with calculation once(random()), this question will be shown half the times that this form is launched
B12: (${computed_months} >= 6 and ${computed_months} < 24) or (${months} >= 6 and ${months} < 24) | C12: Conditions can be combined using and, or
B13: selected(${q1}, 'nurse') | C13: This question will only appear if 'nurse' was selected in q1
B14: selected(${q1}, -88) or selected(${q2}, -88) or selected(${q3}, -88) | C14: This question will appear if -88 was selected in any of q1, q2 and q3
B15: ${q1} < 12.5 or selected(${q2}, 'y') | C15: This question will appear if q1's value was less than 12.5 or if 'y' was selected in q2
B16: not(selected(${q2}, 'b')) | C16: This question will appear if 'b' was not selected in q2
B17: string-length(${q1}) > 3 | C17: This question will appear if the answer to q1 had more than 3 characters
B18: false() | C18: This question will never appear. This can be useful when creating a form that is intended to be customized for different environments. Questions or sections that are optional can be marked as non-relevant in the template.

Sheet 🔒 Constraints
B1: Constraints
B3: Constraints limit the answers allowed in a field.
B4: 💡 Constraints are not evaluated if the answer is blank. To require answers, make the question required.
B5: 💡 You can meet almost any requirement with available functions
B7: Example constraint expression | C7: Description
B8: . <= 10 | C8: Answer must be a number less or equal to 10
B9: . > 10.51 and . < 18.39 | C9: Answer must be a number between 10.51 and 18.39, excluding those values
B10: string-length(.) > 5 | C10: Answer must be longer than 5 characters
B11: . >= today() | C11: Answer must be a date today or later
B12: . >= date('2015-08-01') | C12: Answer must be a date August 1st 2015 or later
B13: count-selected(.) <= 3 | C13: Answer to this multi select question can only include 0, 1, 2 or 3 choices but no more
B14: not(selected(., 'none') and count-selected(.) > 1) | C14: Answer to this multi select question may not include both 'none' and other selections
B15: if(selected(., 'none'), count-selected(.) = 1, true()) | C15: Another way of expressing the same concept as above: if the 'none' choice is selected, the total number of choices selected must be 1. Otherwise, any number of selections is allowed. Replace true() with another expression to specify a requirement when 'none' is not selected
B16: if(selected(., 'none'), count-selected(.) = 1, count-selected(.) = 2) | C16: Answer to this multi select question can either be 'none' or exactly two choices not including 'none'
B17: regex(., '^[A-Za-z]{0,6}$') | C17: Answer to this text question may have up to 6 letters
B18: regex(.,'^[A-Z]{3}+_+[A-Z]{3}+_+[0-9]{4}+_+[0-9]{3,4}$') | C18: Answer must respect a specific structure (for example this one allows the following : CAR_PRC_2015_048)
... B21: . = 9999 or (selected(${q1}, 'yes') and . <= 0) or (selected(${q1}, 'no') and . > 0) | C21: The answer 9999 is always accepted to represent 'unknown'. Otherwise, this question's answer depends on ${q1}'s answer: if ${q1} was 'yes', then this answer must be a negative number. If ${q1} was 'no', this answer must be a positive number.

Sheet 🌐 Translations
B1: Translations
B3: XLSForms can be translated into multiple languages.
B4: 💡 The text on navigation buttons and other system elements are translated as part of the application that shows your form, not as part of the form definition.
B5: 💡 Form titles can't be translated.
B6: 💡 We recommend that you design your form in one language, test it extensively, and then translate it.
B7: 💡 You can specify a default language in the settings sheet.
B8: ⚠️ There is no fallback language. Specify a translation for every column used in the form. Otherwise, a dash (-) will be shown for text that is not translated to the current language.
B9: ⚠️ If you use the choices sheet, make sure that all of its text and media columns have translations for all languages.
B11: Add new language
B12: Duplicate all columns that have user-facing text or media to add new language.
B13: These are highlighted in the survey and choices sheets:
B15: label
... B34: survey
C35: type | D35: name | E35: label::English (en) | F35: label::Español (es) | G35: hint::English (en) | H35: hint::Español (es) | I35: image::English (en) | J35: image::Español (es)
B37: choices
C38: list_name | D38: name | E38: label::English (en) | F38: label::Español (es) | G38: image::English (en) | H38: image::Español (es)

Sheet 🔍 List lookups
B1: List lookups
B3: You can look up values from lists specified in the choices sheet, entity lists, attached CSVs, attached geoJSON files and attached XML files by using the instance function.
B4: 💡 Choice filters, used to filter lists of items for use in selects, are the same as filter expressions
B5: 💡 These queries use a subset of the XPath language. ${} expressions get translated to XPath to access fields in the form
B7: instance('list_name')/root/item[filter expression]/desired_property
B8: list_name | C8: The name of the list to get value(s) from
B9: filter expression | C9: An expression for filtering the items in the list. You can filter the list down to one single item or multiple. Filter expressions can use functions and any other logic.
B10: property | C10: The property you want to access for items that match the filter
B13: Common type of lookup
B14: The most common type of query looks a single item up based on one property and gives back another property's value
B15: instance('list_name')/root/item[match_property = ${q1}]/desired_property
B16: list_name | C16: The name of the list to get value(s) from
B17: match_property | C17: The property used to look up an item
B18: ${q1} | C18: A value used to look up the item (e.g., a unique id)
B19: desired_property | C19: The property whose value is returned
B21: Example query | G21: Description
B22: instance('crops')/root/item[name = ${crop}]/average_yield | G22: In a list of crops, use a previously-entered crop name to look up that crop's average yield.
B23: instance('days')/root/item[number = ${day_number}]/blood_pressure_needed | G23: In a list of days, use a previously-entered day number to look up whether or not blood pressure needs to be entered that day.
B24: instance('data_collectors')/root/item[name = ${data_collector_id}]/visits_complete | G24: In a list of data collector, use a previously-entered data collector id to look up how many visits the data collector completed.
B25: instance('houses')/root/item[name = ${hhid}]/geometry | G25: In a list of houses, use a previously-entered household id to look up the geometry (location) of that house.
B26: count(instance('participants')/root/item[answered = 'no']/label) | G26: Filter a list of participants to only those who have not answered yet. Count the number of matches.
B27: sum(instance('patients')/root/item[birth_year > 1978][gender = 'female']/child_count) | G27: Filter a list of patients to only those with birth year greater than 1978, then filter that list to females only, then get the child count for each of them. The full expression computes the sum of all children of females born after 1978.
B28: instance('children')/root/item[household = ${hhid}][number = position(..)]/first_name | G28: Get the first name of the Nth child in a household with id ${hhid} where N is the position of the current repeat in the list of all repeat instances.
B30: 💡 You can use these expressions with repeats, too. For example, if ${repeat} is a repeat in your form, you can write
B31: ${repeat}[filter expression]/desired_field to access a field in a repeat instance or sum(${repeat}[filter expression]/desired_field) to get the sum of all repeat instances that match the filter.
B33: 💡 If you are looking values up in an attached CSV, you can also use the pulldata function. In Collect, this may have better performance for lists with many tens of thousands of elements.
B34: pulldata(list_name, desired_property, match_property, ${q1})
B36: The pulldata expression above is equivalent to:
B37: instance('list_name')/root/item[match_property = ${q1}]/desired_property

Sheet ✅ Additional columns
B1: Additional columns
B3: The default survey, choices, settings and entities sheets include the most common columns. You may find it useful to add some of the columns described below.
B5: survey sheet | E5: Collect mobile forms | F5: Enketo web forms | G5: Translatable
C6: save_to | D6: When using Entities, used to specify the Entity property to save the form field's value to | E6: Yes | F6: Yes | G6: N/A
C7: guidance_hint | D7: Used to display additional information to data collectors in a way that is less visible than hints | E7: Yes | F7: Yes | G7: Yes
C8: required_message | D8: A custom message to replace the generic message when a required value is not filled in | E8: Yes | F8: Yes | G8: Yes
C9: read_only | D9: An expression used to determine whether the question's value can be edited or not | E9: Yes | F9: Static values only (yes/no) | G9: N/A
C10: big-image | D10: The filename of an image to display when the label image is tapped. Can be translated. | E10: Yes | F10: Yes | G10: Yes
C11: instance::my_attribute | D11: A custom instance attribute which will be included along with its value in submitted data | E11: Yes | F11: Yes | G11: N/A
C12: bind::my_attribute | D12: A custom bind attribute. Generally used when an application has a special custom feature | E12: Yes | F12: Yes | G12: N/A
C13: body::my_attribute | D13: A custom body attribute. Generally used when an application has a special custom feature | E13: Yes | F13: Yes | G13: N/A
B15: choices sheet
C16: image | D16: An image to show with this choice | E16: Yes | F16: Yes | G16: Yes
C17: audio | D17: An audio file to show with this choice | E17: Yes | F17: Yes | G17: Yes
C18: video | D18: A video file to show with this choice | E18: Yes | F18: Yes | G18: Yes
C19: geometry | D19: A special column that represents a choice's point, trace or shape to be displayed on a map with the map appearance | E19: Yes | F19: No | G19: N/A
B21: settings sheet
C22: public_key | D22: Public key for encrypting form instances when your server is not trusted | E22: Yes | F22: Yes | G22: N/A
C23: submission_url | D23: Specify a URL to make submissions to regardless of how the app is configured | E23: Yes | F23: No | G23: N/A
C24: allow_choice_duplicates | D24: Add with 'yes' value if you want a single list on the choices sheet to have multiple choices with the same name | E24: Yes | F24: Yes | G24: N/A
B26: entities sheet
C27: create_if | D27: A condition that a filled form must meet for an entity to be created from it | E27: Yes | F27: Yes | G27: N/A
C28: entity_id | D28: The id of the entity that should be updated by filling this form | E28: Yes | F28: Yes | G28: N/A
C29: update_if | D29: A condition that a filled form must meet for an entity to be updated from it (with entity_id) | E29: Yes | F29: Yes | G29: N/A
